Starting to process data...
No handlers could be found for logger "concurrent.futures"
Traceback (most recent call last):
  File "spindown_sim.py", line 259, in <module>
    seeds = Parallel(n_jobs=10)(delayed(mc)(ind) for ind in range(n_mc))
  File "/home/cblakemore/.local/lib/python2.7/site-packages/joblib/parallel.py", line 934, in __call__
    self.retrieve()
  File "/home/cblakemore/.local/lib/python2.7/site-packages/joblib/parallel.py", line 833, in retrieve
    self._output.extend(job.get(timeout=self.timeout))
  File "/home/cblakemore/.local/lib/python2.7/site-packages/joblib/_parallel_backends.py", line 521, in wrap_future_result
    return future.result(timeout=timeout)
  File "/home/cblakemore/.local/lib/python2.7/site-packages/joblib/externals/loky/_base.py", line 433, in result
    return self.__get_result()
  File "/home/cblakemore/.local/lib/python2.7/site-packages/joblib/externals/loky/_base.py", line 381, in __get_result
    raise self._exception
joblib.externals.loky.process_executor.TerminatedWorkerError: A worker process managed by the executor was unexpectedly terminated. This could be caused by a segmentation fault while calling the function or by an excessive memory usage causing the Operating System to kill the worker. The exit codes of the workers are {SIGKILL(-9)}
